2019-06-05T09:51:22|CRITICAL|root|Unhandled exception:Traceback (most recent call last):
  File "microscope_app.py", line 33, in <module>
    app = OceanOpticsApp(sys.argv)
  File "C:\Users\lindat18\AppData\Local\Continuum\miniconda3\envs\scopefoundry\lib\site-packages\ScopeFoundry\base_app.py", line 338, in __init__
    self.setup()
  File "microscope_app.py", line 17, in setup
    self.add_measurement(PiezoStageMeasure(self))
  File "C:\Users\lindat18\AppData\Local\Continuum\miniconda3\envs\scopefoundry\lib\site-packages\ScopeFoundry\measurement.py", line 93, in __init__
    self.setup()
  File "C:\Users\lindat18\Dropbox\Ginger_Lab\HW_OceanOptics\PiezoStage_measurement.py", line 55, in setup
    self.pi_device_hw = self.app.hardware['piezostage']
  File "C:\Users\lindat18\AppData\Local\Continuum\miniconda3\envs\scopefoundry\lib\site-packages\ScopeFoundry\helper_funcs.py", line 31, in __getitem__
    return self._odict[key]
KeyError: 'piezostage'

