2019-06-05T09:59:18|CRITICAL|root|Unhandled exception:Traceback (most recent call last):
  File "microscope_app.py", line 33, in <module>
    app = OceanOpticsApp(sys.argv)
  File "C:\Users\lindat18\AppData\Local\Continuum\miniconda3\envs\scopefoundry\lib\site-packages\ScopeFoundry\base_app.py", line 338, in __init__
    self.setup()
  File "microscope_app.py", line 23, in setup
    self.add_measurement(PiezoStageMeasure(self))
  File "C:\Users\lindat18\AppData\Local\Continuum\miniconda3\envs\scopefoundry\lib\site-packages\ScopeFoundry\measurement.py", line 93, in __init__
    self.setup()
  File "C:\Users\lindat18\Dropbox\Ginger_Lab\HW_OceanOptics\PiezoStage_measurement.py", line 58, in setup
    self.spec_measure = self.app.measurement['oceanoptics_measure']
AttributeError: 'OceanOpticsApp' object has no attribute 'measurement'

